<robot name="eva">
    <!-- BODY LINKS -->
        <link name="base_link">
        </link>
        <link name="chasis_link">
            <inertial>
                <origin xyz="0 0 0" rpy="0 0 0" />
                <mass value="64.3" />
                <inertia ixx="8.303" ixy="0" ixz="0" iyy="5.468" iyz="0.075" izz="6.02" />
            </inertial>
            <collision>
                <origin rpy="0 0 0" xyz="0 0 0.40" />
                <geometry>
                    <mesh filename="package://deliverybot_description/models/EVA_Body.dae"/>
                </geometry>
            </collision>
            <visual>
                <geometry> 
                    <mesh filename="package://deliverybot_description/models/EVA_Body.dae"/>
                </geometry>
                <origin rpy="0 0 0" xyz="0 0 0.40"/>
            </visual>
        </link>
    <!-- WHEEL LINKS -->
        <link name="fl_tire">
            <inertial>
                <origin xyz="0 0 0" rpy="0 0 0" />
                <mass value="3.512" />
                <inertia ixx="0.02665" ixy="0" ixz="0" iyy="0.0148" iyz="0" izz="0.01479" />
            </inertial>
            <collision>
                <origin rpy="0 0 0" xyz="0 0 0" />
                <geometry>
                    <mesh filename="package://deliverybot_description/models/EVA_Wheel.dae"/>
                </geometry>
            </collision>
            <visual>
                <geometry>
                    <mesh filename="package://deliverybot_description/models/EVA_Wheel.dae"/>
                </geometry>
            </visual>
        </link>
        <gazebo reference="fl_tire">
            <mu1 value="2.0"/> 
            <mu2 value="2.0"/> 
            <kp  value="10000000.0" /> 
            <kd  value="1.0" /> 
            <fdir1 value="0 1 0"/>
        </gazebo>


        <link name="fr_tire">
            <inertial>
                <origin xyz="0 0 0" rpy="0 0 0" />
                <mass value="3.512" />
                <inertia ixx="0.02665" ixy="0" ixz="0" iyy="0.0148" iyz="0" izz="0.01479" />
            </inertial>
            <collision>
                <origin rpy="0 0 0" xyz="0 0 0" />
                <geometry>
                    <mesh filename="package://deliverybot_description/models/EVA_Wheel.dae"/>
                </geometry>
            </collision>
            <visual>
                <geometry>
                    <mesh filename="package://deliverybot_description/models/EVA_Wheel.dae"/>
                </geometry>
            </visual>
        </link>
        <gazebo reference="fr_tire">
            <mu1 value="2.0"/> 
            <mu2 value="2.0"/> 
            <kp  value="10000000.0" /> 
            <kd  value="1.0" /> 
            <fdir1 value="0 1 0"/>
        </gazebo>
        
        <link name="bl_tire">
            <inertial>
                <origin xyz="0 0 0" rpy="0 0 0" />
                <mass value="3.512" />
                <inertia ixx="0.02665" ixy="0" ixz="0" iyy="0.0148" iyz="0" izz="0.01479" />
            </inertial>
            <collision>
                <origin rpy="0 0 0" xyz="0 0 0" />
                <geometry>
                    <mesh filename="package://deliverybot_description/models/EVA_Wheel.dae"/>
                </geometry>
            </collision>
            <visual>
                <geometry>
                    <mesh filename="package://deliverybot_description/models/EVA_Wheel.dae"/>
                </geometry>
            </visual>
        </link>
        <gazebo reference="bl_tire">
            <mu1 value="2.0"/> 
            <mu2 value="2.0"/> 
            <kp  value="10000000.0" /> 
            <kd  value="1.0" /> 
            <fdir1 value="0 1 0"/>
        </gazebo>

        <link name="br_tire">
            <inertial>
                <origin xyz="0 0 0" rpy="0 0 0" />
                <mass value="3.512" />
                <inertia ixx="0.02665" ixy="0" ixz="0" iyy="0.0148" iyz="0" izz="0.01479" />
            </inertial>
            <collision>
                <origin rpy="0 0 0" xyz="0 0 0" />
                <geometry>
                    <mesh filename="package://deliverybot_description/models/EVA_Wheel.dae"/>
                </geometry>
            </collision>
            <visual>
                <geometry>
                    <mesh filename="package://deliverybot_description/models/EVA_Wheel.dae"/>
                </geometry>
            </visual>
        </link>
        <gazebo reference="br_tire">
            <mu1 value="2.0"/> 
            <mu2 value="2.0"/> 
            <kp  value="10000000.0" /> 
            <kd  value="1.0" /> 
            <fdir1 value="0 1 0"/>
        </gazebo>
    <!-- DOOR LINKS -->
        <link name="door">
            <inertial>
                <origin rpy="0 0 0" xyz="0 0 0" />
                <mass value="8" />
                <inertia ixx="0.4381" ixy="0" ixz="0" iyy="0.1637" iyz="0.005" izz="0.6" />
            </inertial>
            <collision>
                <origin rpy="0 0 0" xyz="0 0 0" />
                <geometry>
                    <mesh filename="package://deliverybot_description/models/EVA_Lid.dae" />
                </geometry>
            </collision>
            <visual>
                <geometry>
                    <mesh filename="package://deliverybot_description/models/EVA_Lid.dae" />
                </geometry>
                <origin rpy="0 0 0" xyz="0 .425 0" />
            </visual>
        </link>
    <!-- STEERING LINKS -->
        <link name="left_wheel_assembly">
            <collision>
                <origin xyz="0 0 0" rpy="0 0 0" />
                <geometry>
                    <cylinder length="0.01" radius="0.005" />
                </geometry>
            </collision>
            <visual>
                <origin xyz="0 0 0" rpy="0 0 0" />
                <geometry>
                    <cylinder length="0.01" radius="0.005" />
                </geometry>
            </visual>

            <inertial>
                <origin xyz="0 0 0" rpy="0 0 0" />
                <mass value="0.2" />
                <cylinder_inertia m="0.2" r="0.3" h="0.1" />
                <inertia ixx="0.4" ixy="0.1" ixz="0.1" iyy="0.4" iyz="0.1" izz="0.2" />
            </inertial>
        </link>
        <gazebo reference="left_wheel_assembly">
            <mu1 value="2.0" />
            <mu2 value="2.0" />
            <kp value="10000000.0" />
            <kd value="1.0" />
            <fdir value="0 1 0" />
            <material>Gazebo/Black</material>
        </gazebo>


        <link name="right_wheel_assembly">
            <collision>
                <origin xyz="0 0 0" rpy="0 0 0" />
                <geometry>
                    <cylinder length="0.01" radius="0.005" />
                </geometry>
            </collision>
            <visual>
                <origin xyz="0 0 0" rpy="0 0 0" />
                <geometry>
                    <cylinder length="0.01" radius="0.005" />
                </geometry>
            </visual>

            <inertial>
                <origin xyz="0 0 0" rpy="0 0 1.5708" />
                <mass value="0.2" />
                <cylinder_inertia m="0.2" r="0.3" h="0.1" />
                <inertia ixx="0.4" ixy="0.1" ixz="0.1" iyy="0.4" iyz="0.1" izz="0.2" />
            </inertial>
        </link>
        <gazebo reference="right_wheel_assembly">
            <mu1 value="2.0" />
            <mu2 value="2.0" />
            <kp value="10000000.0" />
            <kd value="1.0" />
            <fdir value="0 1 0" />
            <material>Gazebo/Black</material>
        </gazebo>
        

    <!-- CHASIS JOINTS -->
        <joint name="dummy_joint" type="fixed">
            <parent link="base_link" />
            <child link="chasis_link" />
        </joint>

    <!-- STEERING JOINTS -->
        <joint name="right_wheel_hinge" type="revolute">
            <parent link="chasis_link" />
            <child link="right_wheel_assembly" />
            <origin xyz="0.270 0.3 0" rpy="0 0 0" />
            <axis xyz="0 0 1" rpy="0 0 0" />
            <limit effort="100" velocity="1" lower="-0.75" upper="0.75" />
            <dynamics damping="0.0" friction="0.0" />
        </joint>
        <joint name="left_wheel_hinge" type="revolute">
            <parent link="chasis_link" />
            <child link="left_wheel_assembly" />
            <origin xyz="-0.270 0.3 0" rpy="0 0 0" />
            <axis xyz="0 0 1" rpy="0 0 0" />
            <limit effort="100" velocity="1" lower="-0.75" upper="0.75" />
            <dynamics damping="0.0" friction="0.0" />
        </joint>

    <!-- TIRE JOINTS -->

        <joint name="fl_tire_joint" type="continuous">
            <parent link="left_wheel_assembly"/>
            <child link="fl_tire"/>
            <origin xyz="0 0 0" rpy="0 0 0" />
            <axis xyz="1 0 0" rpy="0 0 0" />
            <limit effort="100" velocity="50" />
            <dynamics damping="0.0" friction="0.0" />
        </joint>

        <joint name="fr_tire_joint" type="continuous">
            <parent link="right_wheel_assembly"/>
            <child link="fr_tire"/>
            <origin xyz="0 0 0" rpy="0 0 3.14" />
            <axis xyz="1 0 0" rpy="0 0 0" />
            <limit effort="100" velocity="50" />
            <dynamics damping="0.0" friction="0.0" />
        </joint>


        <joint name="bl_tire_joint" type="continuous">
            <parent link="chasis_link" />
            <child link="bl_tire" />
            <origin xyz="-0.270 -0.3 0" rpy="0 0 0" />
        </joint>

        <joint name="br_tire_joint" type="continuous">
            <parent link="chasis_link" />
            <child link="br_tire" />
            <origin xyz="0.270 -0.3 0" rpy="0 0 3.14" />
        </joint>


    <!-- DOOR JOINT -->
        <joint name="door_link" type="revolute">
            <limit lower="0" upper="1.57" effort="100" velocity="0.500" />
            <origin rpy="0 0 0" xyz="0 -0.4375 .725" />
            <parent link="chasis_link" />
            <child link="door" />
        </joint>
    
    <!-- TRANSMISSIONS -->
        <transmission name="trans_left_wheel_hinge">
            <type>transmission_interface/SimpleTransmission</type>
            <joint name="left_wheel_hinge">
                <hardwareInterface>hardware_interface/EffortJointInterface</hardwareInterface>
            </joint>
            <actuator name="motor1">
                <hardwareInterface>hardware_interface/EffortJointInterface</hardwareInterface>
                <mechanicalReduction>1</mechanicalReduction>
            </actuator>
        </transmission>

        <transmission name="trans_left_wheel_rotate">
            <type>transmission_interface/SimpleTransmission</type>
            <joint name="fl_tire_joint">
            <hardwareInterface>hardware_interface/EffortJointInterface</hardwareInterface>
            </joint>
            <actuator name="motor_left_wheel_rotate">
            <hardwareInterface>hardware_interface/EffortJointInterface</hardwareInterface>
            <mechanicalReduction>1</mechanicalReduction>
            </actuator>
        </transmission>

        <transmission name="trans_right_wheel_hinge">
            <type>transmission_interface/SimpleTransmission</type>
            <joint name="right_wheel_hinge">
                <hardwareInterface>hardware_interface/EffortJointInterface</hardwareInterface>
            </joint>
            <actuator name="motor2">
                <hardwareInterface>hardware_interface/EffortJointInterface</hardwareInterface>
                <mechanicalReduction>1</mechanicalReduction>
            </actuator>
        </transmission>

        <transmission name="trans_right_wheel_rotate">
            <type>transmission_interface/SimpleTransmission</type>
            <joint name="fr_tire_joint">
            <hardwareInterface>hardware_interface/EffortJointInterface</hardwareInterface>
            </joint>
            <actuator name="motor_right_wheel_rotate">
            <hardwareInterface>hardware_interface/EffortJointInterface</hardwareInterface>
            <mechanicalReduction>1</mechanicalReduction>
            </actuator>
        </transmission>

    <gazebo>
        <plugin name="gazebo_ros_control" filename="libgazebo_ros_control.so">
            <robotNamespace>/</robotNamespace>
        </plugin>
    </gazebo>

</robot>